Workbook

Sheet Tham_so
A1: THAM SỐ ĐẦU VÀO — KHOÁN ĐTLK (đơn vị: đồng)
A3: Giá nhiên liệu (đồng/lít)
A4: Xăng RON 95 | B4: 24000
A5: Dầu DO | B5: 22000
A7: Giá thuê xe PL F & năng lực khai thác
A8: Lớp xe | B8: PL F (đồng/tháng) | C8: Khai thác (giờ/tháng) | D8: Đơn giá giờ (đồng)
A9: Bcar (ô tô con - hạng B) | B9: 8000000 | C9: 260 | D9: =B9/C9 -> 30769.231
A10: C1 (tải 3,5-7,5T) | B10: 10000000 | C10: 260 | D10: =B10/C10 -> 38461.538
A11: C (tải >7,5T) | B11: 13000000 | C11: 260 | D11: =B11/C11 -> 50000
A12: D1 (10-16 chỗ) | B12: 11000000 | C12: 260 | D12: =B12/C12 -> 42307.692
A13: D2 (16-30 chỗ) | B13: 14000000 | C13: 260 | D13: =B13/C13 -> 53846.154
A14: D (>30 chỗ) | B14: 17000000 | C14: 200 | D14: =B14/C14 -> 85000
A16: Hoa hồng Hạng B (đồng) theo số xe
A17: Số xe | B17: Hoa hồng
A18: 0 | B18: 1500000
A19: 1 | B19: 1600000
A20: 2 | B20: 1700000
A21: 3 | B21: 1800000
A22: ≥4 | B22: 2000000

Sheet Dinh_muc
B1: ĐỊNH MỨC TT 14 & TÍNH NL/HV, XE-GIỜ/HV
A3: STT | B3: Hạng | C3: NL sân (l/giờ) | D3: NL đường (l/100km) | E3: Giá NL (đ/l) | F3: Giờ sân | G3: HV/xe | H3: Giờ đường | I3: Km đường | J3: NL/HV - 621 (đ) | K3: Xe-giờ/HV
A4: 1 | B4: B số sàn | C4: 5.6 | D4: 14.3 | E4: =Tham_so!$B$4 -> 24000 | F4: 41 | G4: 5 | H4: 40 | I4: 810 | J4: =C4*(F4/G4)*E4+D4*(I4/100)*E4 -> 3882000 | K4: =F4/G4+H4 -> 48.2
A5: 2 | B5: B số tự động | C5: 5.6 | D5: 14.3 | E5: =Tham_so!$B$4 -> 24000 | F5: 41 | G5: 5 | H5: 24 | I5: 710 | J5: =C5*(F5/G5)*E5+D5*(I5/100)*E5 -> 3538800 | K5: =F5/G5+H5 -> 32.2
A6: 3 | B6: C1 | C6: 8.7 | D6: 18 | E6: =Tham_so!$B$5 -> 22000 | F6: 43 | G6: 8 | H6: 48 | I6: 825 | J6: =C6*(F6/G6)*E6+D6*(I6/100)*E6 -> 4295775 | K6: =F6/G6+H6 -> 53.375
A7: 4 | B7: B→C | C7: 11.9 | D7: 30 | E7: =Tham_so!$B$5 -> 22000 | F7: 7 | G7: 8 | H7: 10 | I7: 210 | J7: =C7*(F7/G7)*E7+D7*(I7/100)*E7 -> 1615075 | K7: =F7/G7+H7 -> 10.875
A8: 5 | B8: C1→C | C8: 11.9 | D8: 30 | E8: =Tham_so!$B$5 -> 22000 | F8: 4 | G8: 8 | H8: 5 | I8: 105 | J8: =C8*(F8/G8)*E8+D8*(I8/100)*E8 -> 823900 | K8: =F8/G8+H8 -> 5.5
A9: 6 | B9: B→D1 | C9: 9.3 | D9: 24 | E9: =Tham_so!$B$5 -> 22000 | F9: 12 | G9: 10 | H9: 15 | I9: 328 | J9: =C9*(F9/G9)*E9+D9*(I9/100)*E9 -> 1977360 | K9: =F9/G9+H9 -> 16.2
A10: 7 | B10: B→D2 | C10: 10.8 | D10: 30 | E10: =Tham_so!$B$5 -> 22000 | F10: 12 | G10: 10 | H10: 15 | I10: 328 | J10: =C10*(F10/G10)*E10+D10*(I10/100)*E10 -> 2449920 | K10: =F10/G10+H10 -> 16.2
A11: 8 | B11: C1→D1 | C11: 9.3 | D11: 24 | E11: =Tham_so!$B$5 -> 22000 | F11: 6 | G11: 10 | H11: 8 | I11: 164 | J11: =C11*(F11/G11)*E11+D11*(I11/100)*E11 -> 988680 | K11: =F11/G11+H11 -> 8.6
A12: 9 | B12: C1→D2 | C12: 10.8 | D12: 30 | E12: =Tham_so!$B$5 -> 22000 | F12: 7 | G12: 10 | H12: 10 | I12: 210 | J12: =C12*(F12/G12)*E12+D12*(I12/100)*E12 -> 1552320 | K12: =F12/G12+H12 -> 10.7
A13: 10 | B13: C→D1 | C13: 9.3 | D13: 24 | E13: =Tham_so!$B$5 -> 22000 | F13: 4 | G13: 10 | H13: 5 | I13: 105 | J13: =C13*(F13/G13)*E13+D13*(I13/100)*E13 -> 636240 | K13: =F13/G13+H13 -> 5.4
A14: 11 | B14: C→D2 | C14: 10.8 | D14: 30 | E14: =Tham_so!$B$5 -> 22000 | F14: 6 | G14: 10 | H14: 8 | I14: 164 | J14: =C14*(F14/G14)*E14+D14*(I14/100)*E14 -> 1224960 | K14: =F14/G14+H14 -> 8.6
A15: 12 | B15: C→D | C15: 12.6 | D15: 37.5 | E15: =Tham_so!$B$5 -> 22000 | F15: 12 | G15: 10 | H15: 15 | I15: 328 | J15: =C15*(F15/G15)*E15+D15*(I15/100)*E15 -> 3038640 | K15: =F15/G15+H15 -> 16.2
A16: 13 | B16: D1→D2 | C16: 10.8 | D16: 30 | E16: =Tham_so!$B$5 -> 22000 | F16: 4 | G16: 10 | H16: 5 | I16: 105 | J16: =C16*(F16/G16)*E16+D16*(I16/100)*E16 -> 788040 | K16: =F16/G16+H16 -> 5.4
A17: 14 | B17: D1→D | C17: 12.6 | D17: 37.5 | E17: =Tham_so!$B$5 -> 22000 | F17: 10 | G17: 10 | H17: 17 | I17: 340 | J17: =C17*(F17/G17)*E17+D17*(I17/100)*E17 -> 3082200 | K17: =F17/G17+H17 -> 18
A18: 15 | B18: D2→D | C18: 12.6 | D18: 37.5 | E18: =Tham_so!$B$5 -> 22000 | F18: 6 | G18: 10 | H18: 8 | I18: 164 | J18: =C18*(F18/G18)*E18+D18*(I18/100)*E18 -> 1519320 | K18: =F18/G18+H18 -> 8.6

Sheet Bo_tach_khoan
B1: BỘ TÁCH KHOÁN ĐTLK — 621/641/622 → công dạy + phương tiện (đồng)
B3: STT | C3: Hạng | D3: Số xe | E3: Đơn giá tổng (LK) | F3: Mức Thanh toán | G3: NL (621) | H3: Hoa hồng (641) | I3: Công đào tạo (622) | J3: Phương tiện | K3: Công dạy
A4: HẠNG Bss | B4: 1 | C4: B số sàn | D4: 0 | E4: 9200000 | F4: 7000000 | G4: =Dinh_muc!J4 -> 3882000 | H4: =Tham_so!$B$18 -> 1500000 | I4: =E4-G4-H4 -> 3818000 | J4: 0 | K4: =I4-J4 -> 3818000
B5: 2 | C5: B số sàn | D5: 1 | E5: 9600000 | F5: 7000000 | G5: =Dinh_muc!J4 -> 3882000 | H5: =Tham_so!$B$19 -> 1600000 | I5: =E5-G5-H5 -> 4118000 | J5: =Tham_so!$D$9*Dinh_muc!K4 -> 1483076.9 | K5: =I5-J5 -> 2634923.1
B6: 3 | C6: B số sàn | D6: 2 | E6: 9700000 | F6: 7000000 | G6: =Dinh_muc!J4 -> 3882000 | H6: =Tham_so!$B$20 -> 1700000 | I6: =E6-G6-H6 -> 4118000 | J6: =Tham_so!$D$9*Dinh_muc!K4 -> 1483076.9 | K6: =I6-J6 -> 2634923.1
B7: 4 | C7: B số sàn | D7: 3 | E7: 9800000 | F7: 7000000 | G7: =Dinh_muc!J4 -> 3882000 | H7: =Tham_so!$B$21 -> 1800000 | I7: =E7-G7-H7 -> 4118000 | J7: =Tham_so!$D$9*Dinh_muc!K4 -> 1483076.9 | K7: =I7-J7 -> 2634923.1
B8: 5 | C8: B số sàn | D8: ≥4 | E8: 10100000 | F8: 7000000 | G8: =Dinh_muc!J4 -> 3882000 | H8: =Tham_so!$B$22 -> 2000000 | I8: =E8-G8-H8 -> 4218000 | J8: =Tham_so!$D$9*Dinh_muc!K4 -> 1483076.9 | K8: =I8-J8 -> 2734923.1
A9: HẠNG Btd | B9: 6 | C9: B số tự động | D9: 0 | E9: 9200000 | F9: 7000000 | G9: =Dinh_muc!J5 -> 3538800 | H9: =Tham_so!$B$18 -> 1500000 | I9: =E9-G9-H9 -> 4161200 | J9: 0 | K9: =I9-J9 -> 4161200
B10: 7 | C10: B số tự động | D10: 1 | E10: 9600000 | F10: 7000000 | G10: =Dinh_muc!J5 -> 3538800 | H10: =Tham_so!$B$19 -> 1600000 | I10: =E10-G10-H10 -> 4461200 | J10: =Tham_so!$D$9*Dinh_muc!K5 -> 990769.23 | K10: =I10-J10 -> 3470430.8
B11: 8 | C11: B số tự động | D11: 2 | E11: 9700000 | F11: 7000000 | G11: =Dinh_muc!J5 -> 3538800 | H11: =Tham_so!$B$20 -> 1700000 | I11: =E11-G11-H11 -> 4461200 | J11: =Tham_so!$D$9*Dinh_muc!K5 -> 990769.23 | K11: =I11-J11 -> 3470430.8
B12: 9 | C12: B số tự động | D12: 3 | E12: 9800000 | F12: 7000000 | G12: =Dinh_muc!J5 -> 3538800 | H12: =Tham_so!$B$21 -> 1800000 | I12: =E12-G12-H12 -> 4461200 | J12: =Tham_so!$D$9*Dinh_muc!K5 -> 990769.23 | K12: =I12-J12 -> 3470430.8
B13: 10 | C13: B số tự động | D13: ≥4 | E13: 10100000 | F13: 7000000 | G13: =Dinh_muc!J5 -> 3538800 | H13: =Tham_so!$B$22 -> 2000000 | I13: =E13-G13-H13 -> 4561200 | J13: =Tham_so!$D$9*Dinh_muc!K5 -> 990769.23 | K13: =I13-J13 -> 3570430.8
A14: HẠNG C | B14: 11 | C14: C1 | D14: 0 | E14: 10000000 | F14: 8000000 | G14: =Dinh_muc!J6 -> 4295775 | H14: =E14-F14 -> 2000000 | I14: =E14-G14-H14 -> 3704225 | J14: 0 | K14: =I14-J14 -> 3704225
B15: 12 | C15: C1 | D15: 1 | E15: 10300000 | F15: 8000000 | G15: =Dinh_muc!J6 -> 4295775 | H15: =E15-F15 -> 2300000 | I15: =E15-G15-H15 -> 3704225 | J15: =Tham_so!$D$10*Dinh_muc!K6 -> 2052884.6 | K15: =I15-J15 -> 1651340.4
B16: 13 | C16: C1 | D16: 2 | E16: 10500000 | F16: 8000000 | G16: =Dinh_muc!J6 -> 4295775 | H16: =E16-F16 -> 2500000 | I16: =E16-G16-H16 -> 3704225 | J16: =Tham_so!$D$10*Dinh_muc!K6 -> 2052884.6 | K16: =I16-J16 -> 1651340.4
A17: NÂNG HẠNG B→C | B17: 14 | C17: B→C | D17: 0 | E17: 6000000 | F17: 5000000 | G17: =Dinh_muc!J7 -> 1615075 | H17: =MAX(E17-F17,0) -> 1000000 | I17: =E17-G17-H17 -> 3384925 | J17: 0 | K17: =I17-J17 -> 3384925
B18: 15 | C18: B→C | D18: 1 | E18: 6000000 | F18: 5000000 | G18: =Dinh_muc!J7 -> 1615075 | H18: =MAX(E18-F18,0) -> 1000000 | I18: =E18-G18-H18 -> 3384925 | J18: =Tham_so!$D$11*Dinh_muc!K7 -> 543750 | K18: =I18-J18 -> 2841175
A19: NÂNG HẠNG C1→C | B19: 16 | C19: C1→C | D19: 0 | E19: 6000000 | F19: 5000000 | G19: =Dinh_muc!J8 -> 823900 | H19: =MAX(E19-F19,0) -> 1000000 | I19: =E19-G19-H19 -> 4176100 | J19: 0 | K19: =I19-J19 -> 4176100
B20: 17 | C20: C1→C | D20: 1 | E20: 7000000 | F20: 5000000 | G20: =Dinh_muc!J8 -> 823900 | H20: =MAX(E20-F20,0) -> 2000000 | I20: =E20-G20-H20 -> 4176100 | J20: =Tham_so!$D$11*Dinh_muc!K8 -> 275000 | K20: =I20-J20 -> 3901100
B21: 18 | C21: C1→C | D21: 2 | E21: 8000000 | F21: 5000000 | G21: =Dinh_muc!J8 -> 823900 | H21: =MAX(E21-F21,0) -> 3000000 | I21: =E21-G21-H21 -> 4176100 | J21: =Tham_so!$D$11*Dinh_muc!K8 -> 275000 | K21: =I21-J21 -> 3901100
A22: NÂNG HẠNG B→D1 | B22: 19 | C22: B→D1 | D22: 0 | E22: 6000000 | F22: 6000000 | G22: =Dinh_muc!J9 -> 1977360 | H22: =MAX(E22-F22,0) -> 0 | I22: =E22-G22-H22 -> 4022640 | J22: 0 | K22: =I22-J22 -> 4022640
B23: 20 | C23: B→D1 | D23: 1 | E23: 7000000 | F23: 6000000 | G23: =Dinh_muc!J9 -> 1977360 | H23: =MAX(E23-F23,0) -> 1000000 | I23: =E23-G23-H23 -> 4022640 | J23: =Tham_so!$D$12*Dinh_muc!K9 -> 685384.62 | K23: =I23-J23 -> 3337255.4
B24: 21 | C24: B→D1 | D24: 2 | E24: 8000000 | F24: 6000000 | G24: =Dinh_muc!J9 -> 1977360 | H24: =MAX(E24-F24,0) -> 2000000 | I24: =E24-G24-H24 -> 4022640 | J24: =Tham_so!$D$12*Dinh_muc!K9 -> 685384.62 | K24: =I24-J24 -> 3337255.4
A25: NÂNG HẠNG B→D2 | B25: 22 | C25: B→D2 | D25: 0 | E25: 6000000 | F25: 7000000 | G25: =Dinh_muc!J10 -> 2449920 | H25: =MAX(E25-F25,0) -> 0 | I25: =E25-G25-H25 -> 3550080 | J25: 0 | K25: =I25-J25 -> 3550080
B26: 23 | C26: B→D2 | D26: 1 | E26: 7000000 | F26: 7000000 | G26: =Dinh_muc!J10 -> 2449920 | H26: =MAX(E26-F26,0) -> 0 | I26: =E26-G26-H26 -> 4550080 | J26: =Tham_so!$D$13*Dinh_muc!K10 -> 872307.69 | K26: =I26-J26 -> 3677772.3
B27: 24 | C27: B→D2 | D27: 2 | E27: 8000000 | F27: 7000000 | G27: =Dinh_muc!J10 -> 2449920 | H27: =MAX(E27-F27,0) -> 1000000 | I27: =E27-G27-H27 -> 4550080 | J27: =Tham_so!$D$13*Dinh_muc!K10 -> 872307.69 | K27: =I27-J27 -> 3677772.3
A28: NÂNG HẠNG C1→D1 | B28: 25 | C28: C1→D1 | D28: 0 | E28: 6000000 | F28: 5000000 | G28: =Dinh_muc!J11 -> 988680 | H28: =MAX(E28-F28,0) -> 1000000 | I28: =E28-G28-H28 -> 4011320 | J28: 0 | K28: =I28-J28 -> 4011320
B29: 26 | C29: C1→D1 | D29: 1 | E29: 7000000 | F29: 5000000 | G29: =Dinh_muc!J11 -> 988680 | H29: =MAX(E29-F29,0) -> 2000000 | I29: =E29-G29-H29 -> 4011320 | J29: =Tham_so!$D$12*Dinh_muc!K11 -> 363846.15 | K29: =I29-J29 -> 3647473.8
B30: 27 | C30: C1→D1 | D30: 2 | E30: 8000000 | F30: 5000000 | G30: =Dinh_muc!J11 -> 988680 | H30: =MAX(E30-F30,0) -> 3000000 | I30: =E30-G30-H30 -> 4011320 | J30: =Tham_so!$D$12*Dinh_muc!K11 -> 363846.15 | K30: =I30-J30 -> 3647473.8
A31: NÂNG HẠNG C1→D2 | B31: 28 | C31: C1→D2 | D31: 0 | E31: 6000000 | F31: 6000000 | G31: =Dinh_muc!J12 -> 1552320 | H31: =MAX(E31-F31,0) -> 0 | I31: =E31-G31-H31 -> 4447680 | J31: 0 | K31: =I31-J31 -> 4447680
B32: 29 | C32: C1→D2 | D32: 1 | E32: 7000000 | F32: 6000000 | G32: =Dinh_muc!J12 -> 1552320 | H32: =MAX(E32-F32,0) -> 1000000 | I32: =E32-G32-H32 -> 4447680 | J32: =Tham_so!$D$13*Dinh_muc!K12 -> 576153.85 | K32: =I32-J32 -> 3871526.2
B33: 30 | C33: C1→D2 | D33: 2 | E33: 8000000 | F33: 6000000 | G33: =Dinh_muc!J12 -> 1552320 | H33: =MAX(E33-F33,0) -> 2000000 | I33: =E33-G33-H33 -> 4447680 | J33: =Tham_so!$D$13*Dinh_muc!K12 -> 576153.85 | K33: =I33-J33 -> 3871526.2
A34: NÂNG HẠNG C→D1 | B34: 31 | C34: C→D1 | D34: 0 | E34: 6000000 | F34: 5000000 | G34: =Dinh_muc!J13 -> 636240 | H34: =MAX(E34-F34,0) -> 1000000 | I34: =E34-G34-H34 -> 4363760 | J34: 0 | K34: =I34-J34 -> 4363760
B35: 32 | C35: C→D1 | D35: 1 | E35: 7000000 | F35: 5000000 | G35: =Dinh_muc!J13 -> 636240 | H35: =MAX(E35-F35,0) -> 2000000 | I35: =E35-G35-H35 -> 4363760 | J35: =Tham_so!$D$12*Dinh_muc!K13 -> 228461.54 | K35: =I35-J35 -> 4135298.5
B36: 33 | C36: C→D1 | D36: 2 | E36: 8000000 | F36: 5000000 | G36: =Dinh_muc!J13 -> 636240 | H36: =MAX(E36-F36,0) -> 3000000 | I36: =E36-G36-H36 -> 4363760 | J36: =Tham_so!$D$12*Dinh_muc!K13 -> 228461.54 | K36: =I36-J36 -> 4135298.5
A37: NÂNG HẠNG C→D2 | B37: 34 | C37: C→D2 | D37: 0 | E37: 6000000 | F37: 6000000 | G37: =Dinh_muc!J14 -> 1224960 | H37: =MAX(E37-F37,0) -> 0 | I37: =E37-G37-H37 -> 4775040 | J37: 0 | K37: =I37-J37 -> 4775040
B38: 35 | C38: C→D2 | D38: 1 | E38: 7000000 | F38: 6000000 | G38: =Dinh_muc!J14 -> 1224960 | H38: =MAX(E38-F38,0) -> 1000000 | I38: =E38-G38-H38 -> 4775040 | J38: =Tham_so!$D$13*Dinh_muc!K14 -> 463076.92 | K38: =I38-J38 -> 4311963.1
B39: 36 | C39: C→D2 | D39: 2 | E39: 8000000 | F39: 6000000 | G39: =Dinh_muc!J14 -> 1224960 | H39: =MAX(E39-F39,0) -> 2000000 | I39: =E39-G39-H39 -> 4775040 | J39: =Tham_so!$D$13*Dinh_muc!K14 -> 463076.92 | K39: =I39-J39 -> 4311963.1
A40: NÂNG HẠNG C→D | B40: 37 | C40: C→D | D40: 0 | E40: 6000000 | F40: 7000000 | G40: =Dinh_muc!J15 -> 3038640 | H40: =MAX(E40-F40,0) -> 0 | I40: =E40-G40-H40 -> 2961360 | J40: 0 | K40: =I40-J40 -> 2961360
B41: 38 | C41: C→D | D41: 1 | E41: 7000000 | F41: 7000000 | G41: =Dinh_muc!J15 -> 3038640 | H41: =MAX(E41-F41,0) -> 0 | I41: =E41-G41-H41 -> 3961360 | J41: =Tham_so!$D$14*Dinh_muc!K15 -> 1377000 | K41: =I41-J41 -> 2584360
...
